
I tensorflow/stream_executor/dso_loader.cc:125] successfully opened CUDA library libcurand.so.7.5 locally
I tensorflow/stream_executor/dso_loader.cc:125] successfully opened CUDA library libcuda.so.1 locally
I tensorflow/stream_executor/dso_loader.cc:125] successfully opened CUDA library libcufft.so.7.5 locally
I tensorflow/stream_executor/dso_loader.cc:125] successfully opened CUDA library libcudnn.so.5.1.3 locally
I tensorflow/stream_executor/dso_loader.cc:125] successfully opened CUDA library libcublas.so.7.5 locally
/home/sdr375/.local/lib/python2.7/site-packages/google/protobuf/__init__.py:37: UserWarning: Module tensorflow was already imported from /share/apps/tensorflow/20161029/python2.7/lib/python2.7/site-packages/tensorflow/__init__.pyc, but /home/sdr375/.local/lib/python2.7/site-packages is being added to sys.path
  __import__('pkg_resources').declare_namespace(__name__)
I tensorflow/core/common_runtime/gpu/gpu_device.cc:944] Found device 0 with properties: 
name: Tesla K80
major: 3 minor: 7 memoryClockRate (GHz) 0.8235
pciBusID 0000:12:00.0
Total memory: 11.25GiB
Free memory: 11.13GiB
I tensorflow/core/common_runtime/gpu/gpu_device.cc:965] DMA: 0 
I tensorflow/core/common_runtime/gpu/gpu_device.cc:975] 0:   Y 
I tensorflow/core/common_runtime/gpu/gpu_device.cc:1034] Creating TensorFlow device (/gpu:0) -> (device: 0, name: Tesla K80, pci bus id: 0000:12:00.0)
WARNING:tensorflow:*******************************************************
WARNING:tensorflow:TensorFlow's V1 checkpoint format is deprecated; V2 will become the default shortly after 10/31/2016.
WARNING:tensorflow:Consider switching to the more efficient V2 format now:
WARNING:tensorflow:   `tf.train.Saver(write_version=tf.train.SaverDef.V2)`
WARNING:tensorflow:to prevent breakage.
WARNING:tensorflow:*******************************************************
W tensorflow/core/framework/op_kernel.cc:968] Invalid argument: indices[7,8] = 10244 is not in [0, 10000)
	 [[Node: Train/Model/embedding_lookup = Gather[Tindices=DT_INT32, Tparams=DT_FLOAT, _class=["loc:@Model/embedding"], validate_indices=true, _device="/job:localhost/replica:0/task:0/cpu:0"](Model/embedding/read, Train/TrainInput/Slice/_63)]]
W tensorflow/core/framework/op_kernel.cc:968] Invalid argument: indices[7,8] = 10244 is not in [0, 10000)
	 [[Node: Train/Model/embedding_lookup = Gather[Tindices=DT_INT32, Tparams=DT_FLOAT, _class=["loc:@Model/embedding"], validate_indices=true, _device="/job:localhost/replica:0/task:0/cpu:0"](Model/embedding/read, Train/TrainInput/Slice/_63)]]
W tensorflow/core/framework/op_kernel.cc:968] Invalid argument: indices[7,8] = 10244 is not in [0, 10000)
	 [[Node: Train/Model/embedding_lookup = Gather[Tindices=DT_INT32, Tparams=DT_FLOAT, _class=["loc:@Model/embedding"], validate_indices=true, _device="/job:localhost/replica:0/task:0/cpu:0"](Model/embedding/read, Train/TrainInput/Slice/_63)]]
Using the non-hierarchical multiscal version of the model
Reading in data...
using dropout
Building training model...
Trainable variables:
[u'Model/embedding:0', u'Model/RNN/MultiRNNCell/Cell0/BasicLSTMCell/Linear/Matrix:0', u'Model/RNN/MultiRNNCell/Cell0/BasicLSTMCell/Linear/Bias:0', u'Model/RNN/MultiRNNCell/Cell1/BasicLSTMCell/Linear/Matrix:0', u'Model/RNN/MultiRNNCell/Cell1/BasicLSTMCell/Linear/Bias:0', u'Model/RNN/MultiRNNCell/Cell2/BasicLSTMCell/Linear/Matrix:0', u'Model/RNN/MultiRNNCell/Cell2/BasicLSTMCell/Linear/Bias:0', u'Model/softmax_w:0', u'Model/softmax_b:0']
Building validation model...
Building testing model...
Epoch: 1 Learning rate: 1.000
Traceback (most recent call last):
  File "train.py", line 413, in <module>
    tf.app.run()
  File "/share/apps/tensorflow/20161029/python2.7/lib/python2.7/site-packages/tensorflow/python/platform/app.py", line 43, in run
    sys.exit(main(sys.argv[:1] + flags_passthrough))
  File "train.py", line 410, in main
    sv.saver.save(session, FLAGS.save_path, global_step=sv.global_step)
  File "/share/apps/python/2.7.6/intel/lib/python2.7/contextlib.py", line 35, in __exit__
    self.gen.throw(type, value, traceback)
  File "/share/apps/tensorflow/20161029/python2.7/lib/python2.7/site-packages/tensorflow/python/training/supervisor.py", line 974, in managed_session
    self.stop(close_summary_writer=close_summary_writer)
  File "/share/apps/tensorflow/20161029/python2.7/lib/python2.7/site-packages/tensorflow/python/training/supervisor.py", line 802, in stop
    stop_grace_period_secs=self._stop_grace_secs)
  File "/share/apps/tensorflow/20161029/python2.7/lib/python2.7/site-packages/tensorflow/python/training/coordinator.py", line 386, in join
    six.reraise(*self._exc_info_to_raise)
  File "/share/apps/tensorflow/20161029/python2.7/lib/python2.7/site-packages/tensorflow/python/training/coordinator.py", line 296, in stop_on_exception
    yield
  File "/share/apps/tensorflow/20161029/python2.7/lib/python2.7/site-packages/tensorflow/python/training/coordinator.py", line 481, in run
    self.run_loop()
  File "/share/apps/tensorflow/20161029/python2.7/lib/python2.7/site-packages/tensorflow/python/training/supervisor.py", line 1004, in run_loop
    self._sv.global_step])
  File "/share/apps/tensorflow/20161029/python2.7/lib/python2.7/site-packages/tensorflow/python/client/session.py", line 717, in run
    run_metadata_ptr)
  File "/share/apps/tensorflow/20161029/python2.7/lib/python2.7/site-packages/tensorflow/python/client/session.py", line 915, in _run
    feed_dict_string, options, run_metadata)
  File "/share/apps/tensorflow/20161029/python2.7/lib/python2.7/site-packages/tensorflow/python/client/session.py", line 965, in _do_run
    target_list, options, run_metadata)
  File "/share/apps/tensorflow/20161029/python2.7/lib/python2.7/site-packages/tensorflow/python/client/session.py", line 985, in _do_call
    raise type(e)(node_def, op, message)
tensorflow.python.framework.errors.InvalidArgumentError: indices[7,8] = 10244 is not in [0, 10000)
	 [[Node: Train/Model/embedding_lookup = Gather[Tindices=DT_INT32, Tparams=DT_FLOAT, _class=["loc:@Model/embedding"], validate_indices=true, _device="/job:localhost/replica:0/task:0/cpu:0"](Model/embedding/read, Train/TrainInput/Slice/_63)]]

Caused by op u'Train/Model/embedding_lookup', defined at:
  File "train.py", line 413, in <module>
    tf.app.run()
  File "/share/apps/tensorflow/20161029/python2.7/lib/python2.7/site-packages/tensorflow/python/platform/app.py", line 43, in run
    sys.exit(main(sys.argv[:1] + flags_passthrough))
  File "train.py", line 368, in main
    m = PTBModel(is_training=True, config=config, input_=train_input)
  File "train.py", line 113, in __init__
    inputs = tf.nn.embedding_lookup(self._embedding, input_.input_data)
  File "/share/apps/tensorflow/20161029/python2.7/lib/python2.7/site-packages/tensorflow/python/ops/embedding_ops.py", line 93, in embedding_lookup
    validate_indices=validate_indices)
  File "/share/apps/tensorflow/20161029/python2.7/lib/python2.7/site-packages/tensorflow/python/ops/gen_array_ops.py", line 1287, in gather
    validate_indices=validate_indices, name=name)
  File "/share/apps/tensorflow/20161029/python2.7/lib/python2.7/site-packages/tensorflow/python/framework/op_def_library.py", line 748, in apply_op
    op_def=op_def)
  File "/share/apps/tensorflow/20161029/python2.7/lib/python2.7/site-packages/tensorflow/python/framework/ops.py", line 2403, in create_op
    original_op=self._default_original_op, op_def=op_def)
  File "/share/apps/tensorflow/20161029/python2.7/lib/python2.7/site-packages/tensorflow/python/framework/ops.py", line 1305, in __init__
    self._traceback = _extract_stack()

InvalidArgumentError (see above for traceback): indices[7,8] = 10244 is not in [0, 10000)
	 [[Node: Train/Model/embedding_lookup = Gather[Tindices=DT_INT32, Tparams=DT_FLOAT, _class=["loc:@Model/embedding"], validate_indices=true, _device="/job:localhost/replica:0/task:0/cpu:0"](Model/embedding/read, Train/TrainInput/Slice/_63)]]



